Workbook

Sheet 🏠 Master Dashboard
A1: 🧬 A7DO GENESIS MIND — Master Dashboard v6
A2: Clean 14-sheet rebuild · All phases 1–8 · Lorraine & China profiles · Default Tick = 0
A3: ⚡ SINGLE INPUT: Edit 🧬 DNA Loop Engine B4 (Current Tick) to advance the entire organism
A5: ⚡ LIVE ORGANISM STATE — All values update from DNA Loop Engine B4
A6: Parameter | B6: Value | C6: Unit | D6: Notes
A7: Current Tick: | B7: ='🧬 DNA Loop Engine'!B4 -> 0 | C7: ticks | D7: ← Edit DNA Loop Engine B4
A8: Current Week: | B8: ='🧬 DNA Loop Engine'!B5 -> 0 | C8: weeks | D8: Tick ÷ 80
A9: Life Stage: | B9: ='🧬 DNA Loop Engine'!B15 -> 0 | D9: From life stage map
A10: Age: | B10: ='🧬 DNA Loop Engine'!B16 -> 0 | D10: Post-birth age
A11: Birth Status: | B11: ='🧬 DNA Loop Engine'!B8 -> 0 | D11: 🎉 BIRTH COMPLETE at Tick 3,200
A12: Cord Status: | B12: ='🧬 DNA Loop Engine'!B22 -> 1 | D12: Severs at birth
A13: Height H(t): | B13: ='🧬 DNA Loop Engine'!B29 -> 0 | C13: cm | D13: 0→177 cm
A14: Mass M(t): | B14: ='🧬 DNA Loop Engine'!B30 -> 0 | C14: kg | D14: 0→70 kg
A15: Heart Rate: | B15: ='🧬 DNA Loop Engine'!B27 -> 0 | C15: bpm | D15: 120→70 bpm
A16: Vocabulary: | B16: =IFERROR(ROUND(50000/(1+EXP(-0.05*('🧬 DNA Loop Engine'!B5-156))),0),0) -> 20 | C16: words | D16: Logistic V(t)
A17: Motor Stage: | B17: =IF('🧬 DNA Loop Engine'!B5>=400,5,IF('🧬 DNA Loop Engine'!B5>=260,4,IF('🧬 DNA Loop Engine'!B5>=160,3,IF('🧬 DNA Loop Engine'!B5>=80,2,1)))) -> 1 | C17: 1–5 | D17: Motor capability
A18: ToM Stage: | B18: =IF('🧬 DNA Loop Engine'!B5>=624,5,IF('🧬 DNA Loop Engine'!B5>=312,4,IF('🧬 DNA Loop Engine'!B5>=208,3,IF('🧬 DNA Loop Engine'!B5>=156,2,1)))) -> 1 | C18: 1–5 | D18: Theory of Mind
A19: Object Permanence: | B19: =IF('🧬 DNA Loop Engine'!B5>=52,3,IF('🧬 DNA Loop Engine'!B5>=44,2,IF('🧬 DNA Loop Engine'!B5>=36,1,0))) -> 0 | C19: 0–3 | D19: Stage
A20: Consciousness C: | B20: =ROUND(MIN(0.05+'🧬 DNA Loop Engine'!B5/3000,1),3) -> 0.05 | C20: 0–1 | D20: EQ_CONS_10
A21: LTM Events: | B21: =MIN(INT('🧬 DNA Loop Engine'!B4*0.96),200000) -> 0 | C21: events | D21: Episodic memory
A22: Growth Factor: | B22: ='🧬 DNA Loop Engine'!B18 -> 0.9 | C22: 0–1 | D22: Physical growth rate
A23: Neural Gain: | B23: ='🧬 DNA Loop Engine'!B19 -> 0.06 | C23: 0–1 | D23: Neural development
A24: Reflex Gain: | B24: ='🧬 DNA Loop Engine'!B20 -> 20 | C24: 0–1 | D24: Reflex arc maturity
A25: Learning Loop: | B25: =IF(MOD('🧬 DNA Loop Engine'!B4,800)=0,"💤 Sleep",IF(MOD('🧬 DNA Loop Engine'!B4,10)=0,"🔁 Repetition",IF(MOD('🧬 DNA Loop Engine'!B4,5)=0,"🤝 Interaction","👁️ Exposure"))) -> 💤 Sleep | D25: 4-stage cycle
A26: Phase 7 Active: | B26: =IF('🧬 DNA Loop Engine'!B4>=96000,"✅ ACTIVE","⏳ Pending Tick 96,000") -> ⏳ Pending Tick 96,000 | D26: Wisdom activation
A27: Wisdom W(t): | B27: =IF('🧬 DNA Loop Engine'!B4>=96000,ROUND(MIN(0.1+(('🧬 DNA Loop Engine'!B5-1200)/800)*0.9,1),3),0) -> 0 | C27: 0–1 | D27: EQ_WISDOM_18
A30: 📈 DEVELOPMENTAL PHASE TIMELINE
A31: Phase | B31: Domain | C31: Tick Range | D31: Week Range | E31: Key Capability | F31: Live Status
A32: Phase 1 | B32: Biology & Embodiment | C32: 0–3,200 | D32: 0–40 | E32: Organ formation · circulatory · reflex arcs | F32: =IF('🧬 DNA Loop Engine'!B4>=3200,"✅ Complete",IF('🧬 DNA Loop Engine'!B4>=0,"⭐ CURRENT","⏳")) -> ⭐ CURRENT
A33: Phase 2 | B33: Sensorimotor | C33: 3,200–6,400 | D33: 40–80 | E33: Sensory integration · proprioception · motor control | F33: =IF('🧬 DNA Loop Engine'!B4>=6400,"✅ Complete",IF('🧬 DNA Loop Engine'!B4>=3200,"⭐ CURRENT","⏳")) -> ⏳
A34: Phase 3 | B34: Core Cognition | C34: 6,400–12,480 | D34: 80–156 | E34: Object permanence · episodic memory · value system | F34: =IF('🧬 DNA Loop Engine'!B4>=12480,"✅ Complete",IF('🧬 DNA Loop Engine'!B4>=6400,"⭐ CURRENT","⏳")) -> ⏳
A35: Phase 4 | B35: Social Cognition | C35: 12,480–49,920 | D35: 156–624 | E35: Theory of Mind · language grounding · scene graph | F35: =IF('🧬 DNA Loop Engine'!B4>=49920,"✅ Complete",IF('🧬 DNA Loop Engine'!B4>=12480,"⭐ CURRENT","⏳")) -> ⏳
A36: Phase 5 | B36: Cultural & World | C36: 49,920–74,880 | D36: 624–936 | E36: World systems · NPC social structure · cultural norms | F36: =IF('🧬 DNA Loop Engine'!B4>=74880,"✅ Complete",IF('🧬 DNA Loop Engine'!B4>=49920,"⭐ CURRENT","⏳")) -> ⏳
A37: Phase 6 | B37: Identity | C37: 74,880–96,000 | D37: 936–1,200 | E37: Self-model · identity schema · skill graph · narrative | F37: =IF('🧬 DNA Loop Engine'!B4>=96000,"✅ Complete",IF('🧬 DNA Loop Engine'!B4>=74880,"⭐ CURRENT","⏳")) -> ⏳
A38: Phase 7 | B38: Wisdom | C38: 96,000+ | D38: 1,200+ | E38: Creativity · wisdom · career · legacy projection | F38: =IF('🧬 DNA Loop Engine'!B4>=96000,"⭐ CURRENT","⏳") -> ⏳
A39: Phase 8 | B39: AGI Architecture | C39: Specified | D39: All stages | E39: Vision · motor · planning · world model | F39: =IF('🧬 DNA Loop Engine'!B4>=0,"📋 Specified","⏳") -> 📋 Specified
A42: 🗂️ COMPLETE SHEET INDEX — 14 Sheets
A43: # | B43: Sheet | C43: Category | D43: Key Content
A44: 0 | B44: 🏠 Master Dashboard | C44: Core | D44: Live organism state · phase timeline · sheet index
A45: 1 | B45: 🧬 DNA Loop Engine | C45: Core | D45: Master tick controller · lifecycle table · all derived formulas
...

Sheet 🧬 DNA Loop Engine
A1: 🧬 A7DO DNA LOOP ENGINE — Master Tick Controller
A2: ⚡ SINGLE INPUT: Change B4 (Current Tick) to advance the entire organism. All 14 sheets update automatically.
A3: Tick 0 = Fertilisation · Tick 3,200 = Birth (Week 40) · Tick 96,000 = Adulthood (Week 1,200)
A5: ⚡ MASTER TICK CONTROL — Edit B4 only
A6: Parameter | B6: Value | C6: Unit | D6: Notes
A7: Current Tick: | B7: 0 | C7: ticks | D7: ← EDIT THIS — 0 to 160,000
A8: Current Week: | B8: =ROUND(B4/80,0) -> 0 | C8: weeks | D8: Tick ÷ 80
A9: Life Stage: | B9: =IFERROR(VLOOKUP(ROUND(B4/80,0),'🧬 DNA Loop Engine'!A42:B56,2,TRUE()),"Embryo") -> Embryo | D9: From life stage map
A10: DNA Phase: | B10: =IF(B5>=40,"POSTNATAL",IF(B5>=36,"BIRTH_READY",IF(B5>=28,"INTEGRATE",IF(B5>=20,"NEURAL_GROW",IF(B5>=12,"REFLEX_ON",IF(B5>=8,"BODY_FORM",IF(B5>=4,"ORG_START","DNA_INIT"))))))) -> DNA_INIT | D10: Developmental phase code
A11: Age: | B11: =IF(B5<40,"Prenatal",ROUND(MAX(0,B5-40)/4.33,1)&" months ("&ROUND(MAX(0,B5-40)/52,2)&" yrs)") -> Prenatal | D11: Post-birth age
A12: Birth Status: | B12: =IF(B4>=3200,"🎉 BIRTH COMPLETE",IF(B4=0,"⏸️ NOT STARTED","🔄 GESTATING")) -> ⏸️ NOT STARTED | D12: Tick ≥ 3,200 = born
A13: Cord Status: | B13: =IF(B4>=3200,"🔌 SEVERED","🔗 CONNECTED") -> 🔗 CONNECTED | D13: Severs at birth
A14: Growth Factor: | B14: =IF(B5>=40,1,IF(B5>=36,0.95,IF(B5>=28,0.8,IF(B5>=20,0.6,IF(B5>=12,0.4,IF(B5>=8,0.25,IF(B5>=4,0.1,0.01))))))) -> 0.01 | C14: 0–1 | D14: Physical growth rate
A15: Neural Gain: | B15: =IF(B5>=40,1,IF(B5>=36,0.8,IF(B5>=28,0.6,IF(B5>=20,0.4,IF(B5>=12,0.25,IF(B5>=8,0.1,0)))))) -> 0 | C15: 0–1 | D15: Neural development
A16: Reflex Gain: | B16: =IF(B5>=40,1,IF(B5>=36,0.8,IF(B5>=28,0.6,IF(B5>=20,0.4,IF(B5>=12,0.2,IF(B5>=8,0.05,0)))))) -> 0 | C16: 0–1 | D16: Reflex arc maturity
A17: Heart Rate: | B17: =IF(B5<40,ROUND(120+B18*30,0),MAX(60,ROUND(147-((B5-40)/52)*47,0))) -> 147 | C17: bpm | D17: 120→70 bpm over life
A18: Height H(t): | B18: =IF(B5<=40,ROUND(50/(1+EXP(-0.2*(B5-20))),1),IF(B5<=936,ROUND(MIN(50+(177-50)*(1-EXP(-0.005*(B5-40))),177),1),177)) -> 0.9 | C18: cm | D18: 0→177 cm
A19: Mass M(t): | B19: =IF(B5<=40,ROUND(3.5/(1+EXP(-0.2*(B5-20))),2),IF(B5<=936,ROUND(MIN(3.5+(70-3.5)*(1-EXP(-0.004*(B5-40))),70),2),70)) -> 0.06 | C19: kg | D19: 0→70 kg
A20: Vocabulary: | B20: =IFERROR(ROUND(50000/(1+EXP(-0.05*(B5-156))),0),0) -> 20 | C20: words | D20: Logistic V(t)
A21: Motor Stage: | B21: =IF(B5>=400,5,IF(B5>=260,4,IF(B5>=160,3,IF(B5>=80,2,1)))) -> 1 | C21: 1–5 | D21: Motor capability
A22: ToM Stage: | B22: =IF(B5>=624,5,IF(B5>=312,4,IF(B5>=208,3,IF(B5>=156,2,1)))) -> 1 | C22: 1–5 | D22: Theory of Mind
A23: Obj Permanence: | B23: =IF(B5>=52,3,IF(B5>=44,2,IF(B5>=36,1,0))) -> 0 | C23: 0–3 | D23: Object permanence stage
A24: Consciousness C: | B24: =ROUND(MIN(0.05+B5/3000,1),3) -> 0.05 | C24: 0–1 | D24: EQ_CONS_10
A25: LTM Events: | B25: =MIN(INT(B4*0.96),200000) -> 0 | C25: events | D25: Episodic memory
A26: Phase 7 Active: | B26: =IF(B4>=96000,"✅ ACTIVE — Wisdom Engine online","⏳ Pending Tick 96,000") -> ⏳ Pending Tick 96,000 | D26: Wisdom activation
A27: Wisdom W(t): | B27: =IF(B4>=96000,ROUND(MIN(0.1+((B5-1200)/800)*0.9,1),3),0) -> 0 | C27: 0–1 | D27: EQ_WISDOM_18
A28: Learning Loop: | B28: =IF(MOD(B4,800)=0,"💤 Sleep",IF(MOD(B4,10)=0,"🔁 Repetition",IF(MOD(B4,5)=0,"🤝 Interaction","👁️ Exposure"))) -> 💤 Sleep | D28: 4-stage cycle
A31: 📐 LIFE STAGE MAP
A32: Week Threshold | B32: Life Stage
A33: 0 | B33: Embryo
A34: 4 | B34: Fetal Early
A35: 12 | B35: Fetal Mid
A36: 28 | B36: Fetal Late
A37: 40 | B37: Newborn
A38: 52 | B38: Infant
A39: 80 | B39: Toddler
A40: 156 | B40: Child
A41: 260 | B41: Pre-Adolescent
A42: 624 | B42: Adolescent
A43: 936 | B43: Young Adult
...

Sheet 📐 Phase 1 — Biology & Embodime
A1: 📐 PHASE 1 — BIOLOGY & EMBODIMENT
A2: Prenatal development · organ formation · body systems · growth curves · energy · spatial coordinates
A3: Source: A7DO_DNA_Master_v6 · Change 🧬 DNA Loop Engine B4 to advance organism
A5: ⚡ LIVE TICK PANEL
A6: Parameter | B6: Value | C6: Unit | D6: Status
A7: Current Tick: | B7: ='🧬 DNA Loop Engine'!B4 -> 0 | C7: ticks
A8: Current Week: | B8: ='🧬 DNA Loop Engine'!B5 -> 0 | C8: weeks
A9: Life Stage: | B9: ='🧬 DNA Loop Engine'!B15 -> 0
A10: Age: | B10: ='🧬 DNA Loop Engine'!B16 -> 0
A11: Birth Status: | B11: ='🧬 DNA Loop Engine'!B8 -> 0
A12: Cord Status: | B12: ='🧬 DNA Loop Engine'!B22 -> 1
A13: Growth Factor: | B13: ='🧬 DNA Loop Engine'!B18 -> 0.9 | C13: 0–1
A14: Heart Rate: | B14: ='🧬 DNA Loop Engine'!B27 -> 0 | C14: bpm
A15: Height H(t): | B15: ='🧬 DNA Loop Engine'!B29 -> 0 | C15: cm
A16: Mass M(t): | B16: ='🧬 DNA Loop Engine'!B30 -> 0 | C16: kg
A17: Neural Gain: | B17: ='🧬 DNA Loop Engine'!B19 -> 0.06 | C17: 0–1
A18: Reflex Gain: | B18: ='🧬 DNA Loop Engine'!B20 -> 20 | C18: 0–1
A21: A. PRENATAL PHASES & ORGAN ACTIVATION
A22: Phase | B22: Week Range | C22: Biological Focus | D22: Activation % | E22: DNA Trigger | F22: Key Organ | G22: Key Event | H22: Live Status
A23: 1 | B23: 0–4 | C23: Embryogenesis | D23: 0–10% | E23: DNA_INIT | F23: Neural plate | G23: Neural Plate Formation | H23: =IF('🧬 DNA Loop Engine'!B5>=4,"✅ Complete",IF('🧬 DNA Loop Engine'!B5>=0,"🔄 Active","⏳")) -> 🔄 Active
A24: 2 | B24: 4–8 | C24: Organogenesis | D24: 10–25% | E24: ORG_START | F24: Heart | G24: Heart Chamber Partition | H24: =IF('🧬 DNA Loop Engine'!B5>=8,"✅ Complete",IF('🧬 DNA Loop Engine'!B5>=4,"🔄 Active","⏳")) -> ⏳
A25: 3 | B25: 8–12 | C25: Body Plan | D25: 25–40% | E25: BODY_FORM | F25: Limbs | G25: Limb Differentiation | H25: =IF('🧬 DNA Loop Engine'!B5>=12,"✅ Complete",IF('🧬 DNA Loop Engine'!B5>=8,"🔄 Active","⏳")) -> ⏳
A26: 4 | B26: 12–20 | C26: Reflex Explosion | D26: 40–60% | E26: REFLEX_ON | F26: Reflex Arcs | G26: First fetal movement Wk 12 | H26: =IF('🧬 DNA Loop Engine'!B5>=20,"✅ Complete",IF('🧬 DNA Loop Engine'!B5>=12,"🔄 Active","⏳")) -> ⏳
A27: 5 | B27: 20–28 | C27: Neural Maturation | D27: 60–80% | E27: NEURAL_GROW | F27: Cerebellum | G27: Predictive circuits online | H27: =IF('🧬 DNA Loop Engine'!B5>=28,"✅ Complete",IF('🧬 DNA Loop Engine'!B5>=20,"🔄 Active","⏳")) -> ⏳
A28: 6 | B28: 28–36 | C28: Pre-Birth Integration | D28: 80–95% | E28: INTEGRATE | F28: Myelination | G28: Faster reflex transmission | H28: =IF('🧬 DNA Loop Engine'!B5>=36,"✅ Complete",IF('🧬 DNA Loop Engine'!B5>=28,"🔄 Active","⏳")) -> ⏳
A29: 7 | B29: 36–40 | C29: Birth Preparation | D29: 95–100% | E29: BIRTH_READY | F29: Lungs | G29: Lung maturation | H29: =IF('🧬 DNA Loop Engine'!B5>=40,"✅ Complete",IF('🧬 DNA Loop Engine'!B5>=36,"🔄 Active","⏳")) -> ⏳
A32: B. BIRTH TRANSITION MATRIX — Live state at current tick
A33: System | B33: Pre-Birth State | C33: Post-Birth State | D33: Trigger Week | E33: Current State | F33: Live Status
A34: Umbilical Cord | B34: Connected | C34: Severed | D34: 40 | E34: =IF('🧬 DNA Loop Engine'!B4>=3200,"Severed","Connected") -> Connected | F34: =IF('🧬 DNA Loop Engine'!B4>=3200,"✂️ SEVERED","🔗 CONNECTED") -> 🔗 CONNECTED
A35: Oxygen Source | B35: Placental | C35: Pulmonary | D35: 40 | E35: =IF('🧬 DNA Loop Engine'!B4>=3200,"Pulmonary","Placental") -> Placental | F35: =IF('🧬 DNA Loop Engine'!B4>=3200,"🫁 PULMONARY","🤰 PLACENTAL") -> 🤰 PLACENTAL
A36: Nutrient Source | B36: Umbilical | C36: Digestive | D36: 40 | E36: =IF('🧬 DNA Loop Engine'!B4>=3200,"Digestive","Umbilical") -> Umbilical | F36: =IF('🧬 DNA Loop Engine'!B4>=3200,"🍼 DIGESTIVE","🔗 UMBILICAL") -> 🔗 UMBILICAL
A37: Ductus Arteriosus | B37: Open | C37: Closed | D37: 40 | E37: =IF('🧬 DNA Loop Engine'!B4>=3200,"Closed","Open") -> Open | F37: =IF('🧬 DNA Loop Engine'!B4>=3200,"🔒 CLOSED","🔓 OPEN") -> 🔓 OPEN
A38: Foramen Ovale | B38: Open | C38: Closed | D38: 40 | E38: =IF('🧬 DNA Loop Engine'!B4>=3200,"Closed","Open") -> Open | F38: =IF('🧬 DNA Loop Engine'!B4>=3200,"🔒 CLOSED","🔓 OPEN") -> 🔓 OPEN
A39: Heartbeat Control | B39: Maternal-Synced | C39: Independent | D39: 40 | E39: =IF('🧬 DNA Loop Engine'!B4>=3200,"Independent","Maternal-Synced") -> Maternal-Synced | F39: =IF('🧬 DNA Loop Engine'!B4>=3200,"💓 INDEPENDENT","🤰 MATERNAL-SYNCED") -> 🤰 MATERNAL-SYNCED
A40: Thermoregulation | B40: Maternal | C40: Self-Regulated | D40: 40 | E40: =IF('🧬 DNA Loop Engine'!B4>=3200,"Self-Regulated","Maternal") -> Maternal | F40: =IF('🧬 DNA Loop Engine'!B4>=3200,"🌡️ SELF-REG","🤰 MATERNAL") -> 🤰 MATERNAL
A41: Cognition Mode | B41: Dormant | C41: Autonomous | D41: 40 | E41: =IF('🧬 DNA Loop Engine'!B4>=3200,"Autonomous","Dormant") -> Dormant | F41: =IF('🧬 DNA Loop Engine'!B4>=3200,"🧠 ACTIVE","💤 DORMANT") -> 💤 DORMANT
A44: C. BODY SYSTEMS — Growth Status by Stage
A45: System | B45: Category | C45: Start Wk | D45: Mature Wk | E45: Current Status | F45: Maturity % | G45: Function
A46: Heart | B46: Circulatory | C46: 6 | D46: 28 | E46: =IF('🧬 DNA Loop Engine'!B5>=28,"✅ Mature",IF('🧬 DNA Loop Engine'!B5>=6,"🔄 Growing","⏳")) -> ⏳ | F46: =IF('🧬 DNA Loop Engine'!B5>=28,"100%",IF('🧬 DNA Loop Engine'!B5>=6,ROUND(('🧬 DNA Loop Engine'!B5-6)/(28-6)*100,0)&"%","0%")) -> 0% | G46: Pumps blood · 120→70 bpm
A47: Lungs | B47: Respiratory | C47: 8 | D47: 36 | E47: =IF('🧬 DNA Loop Engine'!B5>=36,"✅ Mature",IF('🧬 DNA Loop Engine'!B5>=8,"🔄 Growing","⏳")) -> ⏳ | F47: =IF('🧬 DNA Loop Engine'!B5>=36,"100%",IF('🧬 DNA Loop Engine'!B5>=8,ROUND(('🧬 DNA Loop Engine'!B5-8)/(36-8)*100,0)&"%","0%")) -> 0% | G47: Gas exchange · activates at birth
...

Sheet 🦿 Phase 2 — Sensorimotor
A1: 🦿 PHASE 2 — SENSORIMOTOR
A2: Proprioception · motor planning · movement engine · reflex arcs · gait · reaching · FOV coupling
A3: Source: A7DO_DNA_Master_v6 · Change 🧬 DNA Loop Engine B4 to advance organism
A5: ⚡ LIVE TICK PANEL
A6: Parameter | B6: Value | C6: Unit | D6: Status
A7: Current Tick: | B7: ='🧬 DNA Loop Engine'!B4 -> 0 | C7: ticks
A8: Current Week: | B8: ='🧬 DNA Loop Engine'!B5 -> 0 | C8: weeks
A9: Life Stage: | B9: ='🧬 DNA Loop Engine'!B15 -> 0
A12: A. MOTOR STAGE PROGRESSION
A13: Stage | B13: Week Range | C13: Tick Range | D13: Capability | E13: Primitives Available | F13: Live Status
A14: 1 | B14: 0–80 | C14: 0–6,400 | D14: Reflex-only | E14: Grasp · startle · trip reflex | F14: =IF('🧬 DNA Loop Engine'!B5>=80,"✅ Past",IF('🧬 DNA Loop Engine'!B5>=0,"⭐ CURRENT","⏳")) -> ⭐ CURRENT
A15: 2 | B15: 80–160 | C15: 6,400–12,800 | D15: Crawling · crude reach | E15: Posture · Balance (basic) · Reaching (crude) | F15: =IF('🧬 DNA Loop Engine'!B5>=160,"✅ Past",IF('🧬 DNA Loop Engine'!B5>=80,"⭐ CURRENT","⏳")) -> ⏳
A16: 3 | B16: 160–260 | C16: 12,800–20,800 | D16: Walking · improving reach | E16: Balance (stable) · Gait (walking) · Reaching | F16: =IF('🧬 DNA Loop Engine'!B5>=260,"✅ Past",IF('🧬 DNA Loop Engine'!B5>=160,"⭐ CURRENT","⏳")) -> ⏳
A17: 4 | B17: 260–400 | C17: 20,800–32,000 | D17: Coordinated · FOV-coupled | E17: All primitives · Gaze-stabilised walk | F17: =IF('🧬 DNA Loop Engine'!B5>=400,"✅ Past",IF('🧬 DNA Loop Engine'!B5>=260,"⭐ CURRENT","⏳")) -> ⏳
A18: 5 | B18: 400+ | C18: 32,000+ | D18: Skilled — full repertoire | E18: All primitives · running · tool use | F18: =IF('🧬 DNA Loop Engine'!B5>=400,"⭐ CURRENT","⏳") -> ⏳
A21: B. RIGID-BODY DYNAMICS
A22: Equation | B22: Formula | C22: Variables | D22: Description
A23: Equation of motion | B23: M(θ)θ̈ + C(θ,θ̇) + G(θ) + Jc(θ)ᵀλ = τ(θ,θ̇,A) | C23: M=inertia, C=Coriolis, G=gravity | D23: Core physics — governs all movement
A24: Muscle force (Hill) | B24: F_m = A_m · F_max,m · f_length(l_m) · f_velocity(v_m) | C24: A_m=activation | D24: Hill-type muscle model
A25: Joint torque | B25: τ(θ,θ̇,A) = Σ_m B_m(θ) · F_m | C25: B_m=moment arm matrix | D25: Sum of all muscle contributions
A26: IK solution | B26: θ̈_des = J†·ẍ_des + (I−J†J)·θ̈_null | C26: J†=pseudoinverse | D26: Null-space for posture/balance
A27: Inverse dynamics | B27: τ_des = M·θ̈_des + C + G + τ_stab | C27: τ_stab=stabilisation | D27: Required joint torques
A28: Learning reward | B28: r_t = w₁(−||e_x||) + w₂(−energy) + w₃(balance) + w₄(−FOV_err) | C28: w₁=0.4, w₂=0.2, w₃=0.2, w₄=0.1 | D28: Full motor policy reward
A31: C. REFLEXES
A32: Reflex | B32: Trigger | C32: Response | D32: Onset Week | E32: Live Status
A33: Grasp reflex | B33: Palm contact | C33: Finger flexion | D33: 0 | E33: =IF('🧬 DNA Loop Engine'!B5>=0,"✅ Active","⏳") -> ✅ Active
A34: Startle reflex | B34: Sudden sound/movement | C34: Freeze + orient | D34: 0 | E34: =IF('🧬 DNA Loop Engine'!B5>=0,"✅ Active","⏳") -> ✅ Active
A35: Trip reflex | B35: Unexpected foot height error | C35: Hip/knee flexion | D35: 12 | E35: =IF('🧬 DNA Loop Engine'!B5>=12,"✅ Active","⏳") -> ⏳
A36: Fall reflex | B36: CoM outside support polygon | C36: Step or arm extension | D36: 40 | E36: =IF('🧬 DNA Loop Engine'!B5>=40,"✅ Active","⏳") -> ⏳
A37: Collision reflex | B37: Contact force spike | C37: Withdraw limb | D37: 40 | E37: =IF('🧬 DNA Loop Engine'!B5>=40,"✅ Active","⏳") -> ⏳
A38: Gaze stabilisation | B38: Target in FOV | C38: Head/neck tracks target | D38: 80 | E38: =IF('🧬 DNA Loop Engine'!B5>=80,"✅ Active","⏳") -> ⏳

Sheet 🧠 Phase 3 — Core Cognition
A1: 🧠 PHASE 3 — CORE COGNITION
A2: Object permanence · episodic memory · value system TD(λ) · predictive simulation · consciousness
A3: Source: A7DO_DNA_Master_v6 · Change 🧬 DNA Loop Engine B4 to advance organism
A5: ⚡ LIVE TICK PANEL
A6: Parameter | B6: Value | C6: Unit | D6: Status
A7: Current Tick: | B7: ='🧬 DNA Loop Engine'!B4 -> 0 | C7: ticks
A8: Current Week: | B8: ='🧬 DNA Loop Engine'!B5 -> 0 | C8: weeks
A9: Life Stage: | B9: ='🧬 DNA Loop Engine'!B15 -> 0
A12: A. OBJECT PERMANENCE
A13: Stage | B13: Week Range | C13: Capability | D13: Formula | E13: Live Status
A14: 0 | B14: 0–36 | C14: No permanence | D14: conf(obj,t+1) = conf·(1−λ_decay) | E14: =IF('🧬 DNA Loop Engine'!B5>=36,"✅ Past",IF('🧬 DNA Loop Engine'!B5>=0,"⭐ CURRENT","⏳")) -> ⭐ CURRENT
A15: 1 | B15: 36–44 | C15: Partial — searches at last location | D15: conf(obj,t+1) = conf·(1−0.001) + 0.1·visible | E15: =IF('🧬 DNA Loop Engine'!B5>=44,"✅ Past",IF('🧬 DNA Loop Engine'!B5>=36,"⭐ CURRENT","⏳")) -> ⏳
A16: 2 | B16: 44–52 | C16: Finds hidden object at last location | D16: Kalman-filtered position tracking | E16: =IF('🧬 DNA Loop Engine'!B5>=52,"✅ Past",IF('🧬 DNA Loop Engine'!B5>=44,"⭐ CURRENT","⏳")) -> ⏳
A17: 3 | B17: 52+ | C17: Full — trajectory prediction | D17: conf(obj,t+1) = conf·(1−λ) + λ·visible(t) | E17: =IF('🧬 DNA Loop Engine'!B5>=52,"⭐ CURRENT","⏳") -> ⏳
A20: B. EPISODIC MEMORY
A21: Equation | B21: Formula | C21: Variables | D21: Description
A22: Forgetting | B22: m(t) = m_0 · t^(−β_forget) | C22: β_forget=0.5 | D22: Power-law decay
A23: LTM accumulation | B23: LTM(t) = MIN(INT(tick × 0.96), 200,000) | C23: 0.96 events/tick | D23: Episodic events accumulate
A24: Encoding | B24: Every 10 ticks | C24: Attention + emotion gate | D24: Short-term → episodic
A25: Consolidation | B25: Every 800 ticks (sleep) | C25: Dream replay + pruning | D25: Episodic → semantic
A28: C. VALUE SYSTEM TD(λ)
A29: Equation | B29: Formula | C29: Variables | D29: Description
A30: TD error | B30: δ(t) = r(t) + γ_td·V(s_{t+1}) − V(s_t) | C30: γ_td=0.95 | D30: Temporal difference error
A31: Value update | B31: V(s,t+1) = V(s,t) + η·δ(t) | C31: η=0.01 | D31: Value function update
A32: Attachment | B32: Att(t) = bond_lorraine · exp(−pred_error) | C32: bond=0.95 | D32: Caregiver attachment drive
A33: Curiosity | B33: D_cur(t) = η_c · novelty(s) · attention(t) | C33: η_c=0.3 | D33: Novelty-driven exploration
A36: D. PREDICTIVE SIMULATION EQ_PRED_08
A37: Equation | B37: Formula | C37: Variables | D37: Description
A38: Free energy | B38: F = Σ[εᵀ·Π·ε + log|Σ|] | C38: ε=error, Π=precision | D38: Minimised by perception and action
A39: Prediction error | B39: ε_l(t) = x_l(t) − μ_l(t) | C39: x=actual, μ=predicted | D39: Hierarchical error at level l
A40: State update | B40: dμ_l/dt = −κ·ε_l + ∂f_l/∂μ_l·ε_{l+1} | C40: κ=0.3 | D40: Kalman-filtered state estimate
A41: Forward model | B41: x̂(t+n) = f(x(t), a(t), ..., a(t+n-1)) | C41: n=planning horizon | D41: Counterfactual branching
A42: Dream replay | B42: x_dream(t) ~ P(x | memory, prior) | C42: Samples from episodic memory | D42: Sleep consolidation + planning
A43: Active inference | B43: a* = argmin_a F(x̂(t+1|a)) | C43: Minimise predicted free energy | D43: Action selection via prediction

Sheet 🤝 Phase 4 — Social Cognition
A1: 🤝 PHASE 4 — SOCIAL COGNITION
A2: Language grounding · Theory of Mind · scene graph · word learning · speech production · web-hook learning
A3: Source: A7DO_DNA_Master_v6 · Change 🧬 DNA Loop Engine B4 to advance organism
A5: ⚡ LIVE TICK PANEL
A6: Parameter | B6: Value | C6: Unit | D6: Status
A7: Current Tick: | B7: ='🧬 DNA Loop Engine'!B4 -> 0 | C7: ticks
A8: Current Week: | B8: ='🧬 DNA Loop Engine'!B5 -> 0 | C8: weeks
A9: Life Stage: | B9: ='🧬 DNA Loop Engine'!B15 -> 0
A12: A. LANGUAGE GROUNDING STAGES
A13: Stage | B13: Week Range | C13: Grounding Type | D13: Example Words | E13: Formula | F13: Live Status
A14: 1 | B14: 40–80 | C14: Prosodic/emotional | D14: mama, no, up | E14: G(word) = 0.4·visual + 0.2·motor + 0.9·emotion | F14: =IF('🧬 DNA Loop Engine'!B5>=80,"✅ Past",IF('🧬 DNA Loop Engine'!B5>=40,"⭐ CURRENT","⏳")) -> ⏳
A15: 2 | B15: 80–156 | C15: Object-word binding | D15: ball, cup, dog | E15: B(word,obj) = α·visual + β·motor + γ·emotion | F15: =IF('🧬 DNA Loop Engine'!B5>=156,"✅ Past",IF('🧬 DNA Loop Engine'!B5>=80,"⭐ CURRENT","⏳")) -> ⏳
A16: 3 | B16: 156–260 | C16: Action-verb binding | D16: eat, throw, walk | E16: V_verb(action) = Σ_t motor_state(t)·reward(t) | F16: =IF('🧬 DNA Loop Engine'!B5>=260,"✅ Past",IF('🧬 DNA Loop Engine'!B5>=156,"⭐ CURRENT","⏳")) -> ⏳
A17: 4 | B17: 260–624 | C17: Relational/spatial | D17: in, on, near, behind | E17: R(A,B) = classify(pos_A, pos_B, context) | F17: =IF('🧬 DNA Loop Engine'!B5>=624,"✅ Past",IF('🧬 DNA Loop Engine'!B5>=260,"⭐ CURRENT","⏳")) -> ⏳
A18: 5 | B18: 624+ | C18: Abstract/social | D18: justice, love, believe | E18: G(word) = C(t) · ToM · CulturalEmbedding | F18: =IF('🧬 DNA Loop Engine'!B5>=624,"⭐ CURRENT","⏳") -> ⏳
A21: B. THEORY OF MIND STAGES
A22: Stage | B22: Week Range | C22: Capability | D22: Formula | E22: Live Status
A23: 1 | B23: 40–156 | C23: Emotional contagion · joint attention | D23: E_j = f(facial, vocal, postural) | E23: =IF('🧬 DNA Loop Engine'!B5>=156,"✅ Past",IF('🧬 DNA Loop Engine'!B5>=40,"⭐ CURRENT","⏳")) -> ⏳
A24: 2 | B24: 156–208 | C24: Desire inference | D24: D_j = argmax_a E[R_j(a) | obs_j] | E24: =IF('🧬 DNA Loop Engine'!B5>=208,"✅ Past",IF('🧬 DNA Loop Engine'!B5>=156,"⭐ CURRENT","⏳")) -> ⏳
A25: 3 | B25: 208–312 | C25: False belief task · deception | D25: FB(j) = B_j ≠ world_state | E25: =IF('🧬 DNA Loop Engine'!B5>=312,"✅ Past",IF('🧬 DNA Loop Engine'!B5>=208,"⭐ CURRENT","⏳")) -> ⏳
A26: 4 | B26: 312–624 | C26: Second-order beliefs | D26: B_j(t+1) = B_j(t) + η·(obs − B_j(t)) | E26: =IF('🧬 DNA Loop Engine'!B5>=624,"✅ Past",IF('🧬 DNA Loop Engine'!B5>=312,"⭐ CURRENT","⏳")) -> ⏳
A27: 5 | B27: 624+ | C27: Full social cognition · negotiation | D27: P(action_j | ToM_i(j)) = softmax(Q_j(s,a)) | E27: =IF('🧬 DNA Loop Engine'!B5>=624,"⭐ CURRENT","⏳") -> ⏳
A30: C. SEED VOCABULARY (Wk 125)
A31: Word | B31: POS | C31: Bound Object | D31: Visual W | E31: Motor W | F31: Emotion W | G31: Confidence | H31: Status
A32: mama | B32: Noun | C32: lorraine | D32: 0.4 | E32: 0.2 | F32: 0.9 | G32: 0.95 | H32: ✅ Grounded
A33: up | B33: Verb | C33: reach_action | D33: 0.3 | E33: 0.6 | F33: 0.4 | G33: 0.88 | H33: ✅ Grounded
A34: no | B34: Interjection | C34: punishment_signal | D34: 0.1 | E34: 0.2 | F34: 0.8 | G34: 0.91 | H34: ✅ Grounded
A35: more | B35: Determiner | C35: food_object | D35: 0.3 | E35: 0.4 | F35: 0.6 | G35: 0.82 | H35: ✅ Grounded
A36: ball | B36: Noun | C36: toy_ball | D36: 0.7 | E36: 0.5 | F36: 0.3 | G36: 0.61 | H36: 🟡 Partial
A37: eat | B37: Verb | C37: food_action | D37: 0.3 | E37: 0.7 | F37: 0.5 | G37: 0.58 | H37: 🟡 Partial
A38: dog | B38: Noun | C38: animal_category | D38: 0.8 | E38: 0.2 | F38: 0.4 | G38: 0.28 | H38: 🔴 Webhook triggered
A39: learn | B39: Verb | C39: meta_cognition | D39: 0.1 | E39: 0.3 | F39: 0.5 | G39: 0.19 | H39: 🔴 Webhook triggered
A40: friend | B40: Noun | C40: social_bond | D40: 0.4 | E40: 0.2 | F40: 0.8 | G40: 0.22 | H40: 🔴 Webhook triggered

Sheet 🌍 Phase 5 — Cultural & World
A1: 🌍 PHASE 5 — CULTURAL & WORLD
A2: World systems · NPC social network · BeenFore City · cultural embedding · environmental context
A3: Source: A7DO_DNA_Master_v6 · Change 🧬 DNA Loop Engine B4 to advance organism
A5: ⚡ LIVE TICK PANEL
A6: Parameter | B6: Value | C6: Unit | D6: Status
A7: Current Tick: | B7: ='🧬 DNA Loop Engine'!B4 -> 0 | C7: ticks
A8: Current Week: | B8: ='🧬 DNA Loop Engine'!B5 -> 0 | C8: weeks
A9: Life Stage: | B9: ='🧬 DNA Loop Engine'!B15 -> 0
A12: A. CULTURAL DEVELOPMENTAL STAGES
A13: Stage | B13: Week Range | C13: Capability | D13: Key Acquisition | E13: Live Status
A14: 0 | B14: 0–40 | C14: Prenatal — no cultural exposure | D14: None | E14: =IF('🧬 DNA Loop Engine'!B5>=40,"✅ Past",IF('🧬 DNA Loop Engine'!B5>=0,"⭐ CURRENT","⏳")) -> ⭐ CURRENT
A15: 1 | B15: 40–156 | C15: Passive cultural absorption | D15: Prosodic patterns · emotional tone · caregiver routines | E15: =IF('🧬 DNA Loop Engine'!B5>=156,"✅ Past",IF('🧬 DNA Loop Engine'!B5>=40,"⭐ CURRENT","⏳")) -> ⏳
A16: 2 | B16: 156–312 | C16: Active cultural participation | D16: Social scripts · turn-taking · play rules | E16: =IF('🧬 DNA Loop Engine'!B5>=312,"✅ Past",IF('🧬 DNA Loop Engine'!B5>=156,"⭐ CURRENT","⏳")) -> ⏳
A17: 3 | B17: 312–624 | C17: Cultural norm internalisation | D17: Values · moral intuitions · social expectations | E17: =IF('🧬 DNA Loop Engine'!B5>=624,"✅ Past",IF('🧬 DNA Loop Engine'!B5>=312,"⭐ CURRENT","⏳")) -> ⏳
A18: 4 | B18: 624–1200 | C18: Deep cultural embedding | D18: Cultural identity · ethical framework | E18: =IF('🧬 DNA Loop Engine'!B5>=1200,"✅ Past",IF('🧬 DNA Loop Engine'!B5>=624,"⭐ CURRENT","⏳")) -> ⏳
A19: 5 | B19: 1200+ | C19: Cultural transmission | D19: Teaching · mentoring · legacy | E19: =IF('🧬 DNA Loop Engine'!B5>=1200,"⭐ CURRENT","⏳") -> ⏳
A22: B. NPC SOCIAL NETWORK
A23: NPC ID | B23: Name | C23: Role | D23: Bond | E23: Cultural Role | F23: Norms Transmitted | G23: World X | H23: World Y
A24: NPC_LORRAINE | B24: Lorraine | C24: Primary caregiver | D24: 0.95 | E24: Cultural anchor | F24: Language · values · safety norms | G24: 1090 | H24: 880
A25: NPC_ALEXIS | B25: Alexis | C25: Extended family | D25: 0.7 | E25: Secondary model | F25: Social norms · play rules | G25: 1050 | H25: 900
A26: NPC_EVELYN | B26: Evelyn | C26: Secondary family | D26: 0.65 | E26: Peer model | F26: Play scripts · sharing norms | G26: 1050 | H26: 900
A27: NPC_JAMES | B27: James | C27: Neighbour | D27: 0.3 | E27: Community member | F27: Community norms | G27: 1100 | H27: 870
A30: C. BEENFORE CITY — Place Registry
A31: Place ID | B31: Label | C31: Type | D31: World X | E31: World Y | F31: Persistence | G31: Cultural Role
A32: PLACE_HOSPITAL | B32: Hospital (Birth) | C32: Building | D32: 0 | E32: 0 | F32: 1 | G32: World origin — birth location
A33: PLACE_H8 | B33: A7DO Home (H8) | C33: House | D33: 1090 | E33: 880 | F33: 1 | G33: Primary cultural context — Lorraine
A34: PLACE_H1 | B34: H1 — Alexis & Evelyn | C34: House | D34: 1050 | E34: 900 | F34: 0.8 | G34: Extended family cultural space
A35: PLACE_H7 | B35: H7 — James & Olivia | C35: House | D35: 1100 | E35: 870 | F35: 0.6 | G35: Neighbour cultural space
A36: PLACE_BEDROOM | B36: Bedroom | C36: Room | D36: 1090 | E36: 882 | F36: 1 | G36: Sleep · dreams · consolidation
A37: PLACE_LIVING | B37: Living Room | C37: Room | D37: 1090 | E37: 878 | F37: 1 | G37: Play · language · NPC interaction
A38: PLACE_KITCHEN | B38: Kitchen | C38: Room | D38: 1092 | E38: 880 | F38: 1 | G38: Feeding · routine · bonding
A39: PLACE_GARDEN | B39: Garden | C39: Outdoor | D39: 1090 | E39: 875 | F39: 0.9 | G39: Exploration · curiosity · motor
A40: PLACE_LANE | B40: BeenFore Lane | C40: Street | D40: 1090 | E40: 860 | F40: 1 | G40: Community · social exposure
A41: PLACE_CITY | B41: BeenFore City | C41: City | D41: 1000 | E41: 1000 | F41: 1 | G41: Cultural centre — world reference

Sheet 🪪 Phase 6 — Identity
A1: 🪪 PHASE 6 — IDENTITY
A2: Self-model · identity schema · skill graph · personal narrative · value consolidation · meta-cognition
A3: Source: A7DO_DNA_Master_v6 · Change 🧬 DNA Loop Engine B4 to advance organism
A5: ⚡ LIVE TICK PANEL
A6: Parameter | B6: Value | C6: Unit | D6: Status
A7: Current Tick: | B7: ='🧬 DNA Loop Engine'!B4 -> 0 | C7: ticks
A8: Current Week: | B8: ='🧬 DNA Loop Engine'!B5 -> 0 | C8: weeks
A9: Life Stage: | B9: ='🧬 DNA Loop Engine'!B15 -> 0
A12: A. IDENTITY DEVELOPMENTAL STAGES
A13: Stage | B13: Week Range | C13: Milestone | D13: Key Process | E13: Live Status
A14: 0 | B14: 0–40 | C14: Prenatal — no self | D14: No self-other distinction | E14: =IF('🧬 DNA Loop Engine'!B5>=40,"✅ Past",IF('🧬 DNA Loop Engine'!B5>=0,"⭐ CURRENT","⏳")) -> ⭐ CURRENT
A15: 1 | B15: 40–156 | C15: Proto-self | D15: Recognises own body · distinguishes self from world | E15: =IF('🧬 DNA Loop Engine'!B5>=156,"✅ Past",IF('🧬 DNA Loop Engine'!B5>=40,"⭐ CURRENT","⏳")) -> ⏳
A16: 2 | B16: 156–312 | C16: Embodied self | D16: Consistent body image · motor competence identity | E16: =IF('🧬 DNA Loop Engine'!B5>=312,"✅ Past",IF('🧬 DNA Loop Engine'!B5>=156,"⭐ CURRENT","⏳")) -> ⏳
A17: 3 | B17: 312–624 | C17: Social self | D17: Bond-based identity · social role awareness | E17: =IF('🧬 DNA Loop Engine'!B5>=624,"✅ Past",IF('🧬 DNA Loop Engine'!B5>=312,"⭐ CURRENT","⏳")) -> ⏳
A18: 4 | B18: 624–936 | C18: Narrative self | D18: Episodic memory → coherent self-narrative | E18: =IF('🧬 DNA Loop Engine'!B5>=936,"✅ Past",IF('🧬 DNA Loop Engine'!B5>=624,"⭐ CURRENT","⏳")) -> ⏳
A19: 5 | B19: 936–1200 | C19: Value self | D19: Value consolidation · moral identity | E19: =IF('🧬 DNA Loop Engine'!B5>=1200,"✅ Past",IF('🧬 DNA Loop Engine'!B5>=936,"⭐ CURRENT","⏳")) -> ⏳
A20: 6 | B20: 1200+ | C20: Wisdom self | D20: Long-horizon self · legacy awareness | E20: =IF('🧬 DNA Loop Engine'!B5>=1200,"⭐ CURRENT","⏳") -> ⏳
A23: B. IDENTITY EQUATIONS
A24: Equation | B24: Formula | C24: Variables | D24: Description
A25: Identity vector | B25: I(t) = [personality, values, goals, skills, narrative, bonds] | C25: 6-component vector | D25: Stable adult identity
A26: Personality stability | B26: P(t+1) = P(t) + η_p·(experience − P(t)) | C26: η_p=0.001 | D26: Traits stabilise through adolescence
A27: Value consolidation | B27: V_stable(t) = EMA(V_system(t), τ=1000) | C27: Exponential moving average | D27: Short-term values → stable preferences
A28: Skill mastery | B28: S_k(t+1) = S_k(t) + η_s·(practice_k − S_k(t)) | C28: η_s=0.01 | D28: 22-dimensional skill mastery vector
A29: Narrative coherence | B29: NC(t) = sim(self_model, episodic_history) | C29: Cosine similarity | D29: How consistent the self-story is
A30: Identity confidence | B30: IC(t) = 1 − Var(I(t), last_1000_ticks) | C30: Low variance = stable | D30: Stability of identity over time
A33: C. 22-DIMENSION SKILL GRAPH
A34: Skill ID | B34: Domain | C34: Current Mastery (Wk 125) | D34: Adult Target | E34: Identity Role
A35: SK_01 | B35: Language & Communication | C35: 0.72 | D35: 0.95 | E35: Core identity expression
A36: SK_02 | B36: Logical Reasoning | C36: 0.68 | D36: 0.9 | E36: Problem-solving identity
A37: SK_03 | B37: Spatial Navigation | C37: 0.81 | D37: 0.85 | E37: World-model competence
A38: SK_04 | B38: Social Cognition (ToM) | C38: 0.65 | D38: 0.95 | E38: Social identity anchor
A39: SK_05 | B39: Emotional Regulation | C39: 0.59 | D39: 0.9 | E39: Emotional identity stability
A40: SK_06 | B40: Motor Coordination | C40: 0.88 | D40: 0.9 | E40: Embodied identity
A41: SK_07 | B41: Creative Synthesis | C41: 0.45 | D41: 0.85 | E41: Creative identity (Phase 7)
A42: SK_08 | B42: Ethical Reasoning | C42: 0.52 | D42: 0.9 | E42: Moral identity (Phase 7)
A43: SK_09 | B43: Long-term Planning | C43: 0.41 | D43: 0.88 | E43: Future-oriented identity
A44: SK_10 | B44: Memory & Recall | C44: 0.77 | D44: 0.85 | E44: Narrative identity source
A45: SK_11 | B45: Pattern Recognition | C45: 0.74 | D45: 0.88 | E45: Analytical identity
A46: SK_12 | B46: Causal Reasoning | C46: 0.63 | D46: 0.9 | E46: Explanatory identity
... A56: SK_22 | B56: Legacy Thinking | C56: 0.38 | D56: 0.9 | E56: Transcendent identity (Phase 7)

Sheet ✨ Phase 7 — Wisdom
A1: ✨ PHASE 7 — WISDOM
A2: Creative Synthesis (EQ_CREAT_17) · Wisdom Index (EQ_WISDOM_18) · Career (EQ_CAREER_19) · Legacy (EQ_LEGACY_20)
A3: Source: A7DO_DNA_Master_v6 · Change 🧬 DNA Loop Engine B4 to advance organism
A5: ⚡ LIVE TICK PANEL
A6: Parameter | B6: Value | C6: Unit | D6: Status
A7: Current Tick: | B7: ='🧬 DNA Loop Engine'!B4 -> 0 | C7: ticks
A8: Current Week: | B8: ='🧬 DNA Loop Engine'!B5 -> 0 | C8: weeks
A9: Life Stage: | B9: ='🧬 DNA Loop Engine'!B15 -> 0
A12: A. PHASE 7 EQUATIONS
A13: Equation | B13: Formula | C13: Parameters | D13: Description | E13: Fires Every
A14: EQ_CREAT_17 | B14: C_new(t) = α_c·(M_episodic ⊕ M_semantic) + β_c·(P_sim ⊗ S_skills) + γ_c·Noise | C14: α_c=0.4, β_c=0.4, γ_c=0.2 | D14: Creative synthesis | E14: 500 ticks
A15: EQ_WISDOM_18 | B15: W(t+1) = W(t) + η_w·[λ1·C50yr + λ2·EthicalWeight + λ3·EmpathyIndex − λ4·ImpulseDrive] | C15: η_w=0.01, λ1=0.4, λ2=0.3, λ3=0.2, λ4=0.1 | D15: Wisdom index W(t) ∈ [0,1] | E15: 500 ticks
A16: EQ_CAREER_19 | B16: Career(t+1) = Career(t) + η_car·[SkillVector · OpportunityMatrix · IdentityVector] | C16: η_car=0.02, S∈R^22 | D16: Career specialisation | E16: 1000 ticks
A17: EQ_LEGACY_20 | B17: L(t+1) = L(t) + η_l·[Impact_direct + Impact_indirect + CulturalTransmission − Entropy_f·L(t)] | C17: η_l=0.005, Entropy_f=0.001 | D17: Legacy projection L(t) ∈ [0,∞) | E17: 2000 ticks
A20: B. WISDOM GROWTH TRAJECTORY
A21: Week | B21: Tick | C21: W(t) | D21: Creativity | E21: Career | F21: Legacy | G21: Dominant Factor
A22: 1200 | B22: 96000 | C22: 0.1 | D22: 0.3 | E22: 0.01 | F22: 0 | G22: Phase 7 activation
A23: 1300 | B23: 104000 | C23: 0.22 | D23: 0.37 | E23: 0.05 | F23: 0.08 | G23: EthicalWeight rising
A24: 1400 | B24: 112000 | C24: 0.38 | D24: 0.44 | E24: 0.11 | F24: 0.19 | G24: EmpathyIndex growing
A25: 1600 | B25: 128000 | C25: 0.63 | D25: 0.58 | E25: 0.25 | F25: 0.41 | G25: Balanced all factors
A26: 1800 | B26: 144000 | C26: 0.8 | D26: 0.72 | E26: 0.4 | F26: 0.67 | G26: Consequence_50yr dominant
A27: 2000 | B27: 160000 | C27: 0.95 | D27: 0.86 | E27: 0.55 | F27: 0.94 | G27: All factors converged

Sheet 🚀 Phase 8 — AGI Architecture
A1: 🚀 PHASE 8 — AGI ARCHITECTURE
A2: Vision V1 · Motor Intelligence M1 · Planning P2 · Social Cognition S2 · Meta-Cognition R2 · World Model W2
A3: Source: A7DO_DNA_Master_v6 · Change 🧬 DNA Loop Engine B4 to advance organism
A5: ⚡ LIVE TICK PANEL
A6: Parameter | B6: Value | C6: Unit | D6: Status
A7: Current Tick: | B7: ='🧬 DNA Loop Engine'!B4 -> 0 | C7: ticks
A8: Current Week: | B8: ='🧬 DNA Loop Engine'!B5 -> 0 | C8: weeks
A9: Life Stage: | B9: ='🧬 DNA Loop Engine'!B15 -> 0
A12: A. AGI READINESS ASSESSMENT
A13: Domain | B13: v1.0 | C13: Phase 8 | D13: Gap Closed | E13: v2.0 Target
A14: Biological body | B14: 85% | C14: 88% | D14: +3% | E14: Full embodied sensing
A15: Neural dynamics | B15: 80% | C15: 83% | D15: +3% | E15: Full cortical model
A16: Language & grounding | B16: 65% | C16: 78% | D16: +13% | E16: Sensorimotor language
A17: Cognitive architecture | B17: 60% | C17: 80% | D17: +20% | E17: Complete cognitive stack
A18: Perception & vision | B18: 55% | C18: 82% | D18: +27% | E18: Full visual cognition
A19: Motor intelligence | B19: 50% | C19: 78% | D19: +28% | E19: Full motor planning
A20: Social & ToM | B20: 30% | C20: 68% | D20: +38% | E20: Full social intelligence
A21: World & continuity | B21: 25% | C21: 70% | D21: +45% | E21: Persistent living world
A22: OVERALL | B22: 54% | C22: 76% | D22: +22% | E22: Fully integrated agent
A25: B. PHASE 8 MODULES
A26: Module | B26: Code | C26: Key Formula | D26: AGI Domain Improved | E26: Status
A27: Vision System | B27: V1 | C27: S(x,y) = w_e·edge + w_m·motion + w_n·novelty | D27: Perception: 55%→82% | E27: Specified
A28: Motor Intelligence | B28: M1 | C28: x̂(t+1) = f_fwd(θ(t), A(t)) | D28: Motor: 50%→78% | E28: Specified
A29: Planning Engine | B29: P2 | C29: V(s) = R(s) + γ·max_a V(T(s,a)) | D29: Cognitive: 60%→80% | E29: Specified
A30: Social Cognition | B30: S2 | C30: M_j = {B_j, D_j, I_j, E_j, bond_j} | D30: Social: 30%→68% | E30: Specified
A31: Meta-Cognition | B31: R2 | C31: c_domain = success_rate(tasks, last_100) | D31: Consciousness: 50%→72% | E31: Specified
A32: World Model | B32: W2 | C32: s(t+1) = s_pred(t+1) + K·ε(t+1) | D32: World: 25%→70% | E32: Specified

Sheet 🔄 Learning Loop
A1: 🔄 LEARNING LOOP — Experience-First Architecture
A2: A7DO learns ONLY through interaction → repetition → sleep consolidation. No pre-loaded knowledge.
A3: Source: A7DO_DNA_Master_v6 · Change 🧬 DNA Loop Engine B4 to advance organism
A5: ⚡ LIVE TICK PANEL
A6: Parameter | B6: Value | C6: Unit | D6: Status
A7: Current Tick: | B7: ='🧬 DNA Loop Engine'!B4 -> 0 | C7: ticks
A8: Current Week: | B8: ='🧬 DNA Loop Engine'!B5 -> 0 | C8: weeks
A9: Life Stage: | B9: ='🧬 DNA Loop Engine'!B15 -> 0
A12: A. 4-STAGE LEARNING CYCLE
A13: Stage | B13: Name | C13: Fires Every | D13: Key Engines | E13: Output
A14: 1 | B14: Exposure | C14: Every tick | D14: EQ_SENS_06 · EQ_EMOT_07 · EQ_ATTN_09 | E14: Sensory vector · attention · emotional delta
A15: 2 | B15: Interaction | C15: Every 5 ticks | D15: EQ_PRED_08 · Motor Planning · Value TD(λ) | E15: Reinforcement · motor update · error reduction
A16: 3 | B16: Repetition | C16: Every 10 ticks | D16: EQ_LANG_12 · G(word) · Scene Graph · ToM | E16: Word-object bindings · concept formation
A17: 4 | B17: Sleep Consolidation | C17: Every 800 ticks | D17: Episodic Memory · EQ_PRED_08 dream replay | E17: Stable knowledge · grounded language · pruned LTM
A20: B. WORD LEARNING PIPELINE — 8 Steps
A21: Step | B21: Process | C21: Formula | D21: Engine | E21: Status
A22: 1 | B22: Exposure — hears word + sees object | C22: S(t) = τ·Stimulus + υ·Attention | D22: EQ_SENS_06 | E22: ✅ Running
A23: 2 | B23: Attention spikes on novel stimulus | C23: A(t) = α1·Intensity·(1+novelty) − β1·H | D23: EQ_ATTN_09 | E23: ✅ Running
A24: 3 | B24: Prediction error spikes | C24: ε_l(t) = x_l(t) − μ_l(t) | D24: EQ_PRED_08 | E24: ✅ Running
A25: 4 | B25: Emotional valence tags event | C25: H(t+1) = H(t) + φ·reward − χ·punishment | D25: EQ_EMOT_07 | E25: ✅ Running
A26: 5 | B26: Event stored in episodic memory | C26: m(t) = m_0 · t^(−β_forget) | D26: Episodic Memory | E26: ✅ Running
A27: 6 | B27: Repetition strengthens binding | C27: B(word,obj) = α·visual + β·motor + γ·emotion | D27: EQ_LANG_12 | E27: 🟡 Partial
A28: 7 | B28: Sleep: dream replay binds word→percept | C28: x_dream(t) ~ P(x | memory, prior) | D28: EQ_PRED_08 | E28: ✅ Running
A29: 8 | B29: Stable word-object binding emerges | C29: G(word) = Σ_m w_m·f_m(percept) | D29: Language Grounding | E29: 🟡 Partial
A32: C. WEB-HOOK LEARNING PIPELINE
A33: Step | B33: Process | C33: Trigger | D33: Engine
A34: 1 | B34: Unknown word encountered | C34: conf(word) < ε=0.3 | D34: Word Learning Engine
A35: 2 | B35: Curiosity spike | C35: D_curiosity = η_c · novelty · attention | D35: EQ_ATTN_09 + Value System
A36: 3 | B36: Query: word + context + FOV + state | C36: External API call | D36: Web-Hook API
A37: 4 | B37: Response + age-gate filter | C37: JSON webhook_data | D37: H.4 Algorithm
A38: 5 | B38: Semantic integration | C38: W ← W ∪ webhook_data | D38: Word Learning Engine
A39: 6 | B39: Confidence update + episodic encoding | C39: conf ← conf + boost | D39: Episodic Memory
A40: 7 | B40: Sleep consolidation | C40: Next 800-tick sleep | D40: Learning Loop Stage 4

Sheet ⚙️ System Reference
A1: ⚙️ SYSTEM REFERENCE — Parameters · Equations · Engine Registry
A2: All 52 biological constants · 24 engine registry · tick frequency schedule
A3: Source: A7DO_DNA_Master_v6 · Change 🧬 DNA Loop Engine B4 to advance organism
A5: A. GLOBAL PARAMETERS — 52 Biological Constants
A6: Symbol | B6: Name | C6: Value | D6: Min | E6: Max | F6: Engine / Domain
A7: α | B7: Growth coefficient (primary) | C7: 0.05 | D7: 0.01 | E7: 0.1 | F7: EQ_DNA_01
A8: β | B8: Growth coefficient (secondary) | C8: 0.05 | D8: 0.01 | E8: 0.1 | F8: EQ_DNA_01
A9: γ | B9: Maturity index coefficient | C9: 0.05 | D9: 0.01 | E9: 0.1 | F9: EQ_DNA_01
A10: δ | B10: Cell division rate constant | C10: 0.5 | D10: 0.1 | E10: 1 | F10: EQ_ANAT_02
A11: ε | B11: Nutrient flow constant | C11: 0.5 | D11: 0.1 | E11: 1 | F11: EQ_ANAT_02
A12: ζ | B12: Oxygen exchange constant | C12: 0.5 | D12: 0.1 | E12: 1 | F12: EQ_ANAT_02
A13: η | B13: Waste removal rate | C13: 0.5 | D13: 0.1 | E13: 1 | F13: EQ_ANAT_02
A14: θ | B14: Synapse density coefficient | C14: 0.025 | D14: 0.001 | E14: 0.05 | F14: EQ_NEUR_03
A15: ι | B15: Neural gain coefficient | C15: 0.025 | D15: 0.001 | E15: 0.05 | F15: EQ_NEUR_03
A16: κ | B16: Input signal multiplier | C16: 0.025 | D16: 0.001 | E16: 0.05 | F16: EQ_NEUR_03
A17: λ | B17: Noise attenuation factor | C17: 0.025 | D17: 0.001 | E17: 0.05 | F17: EQ_NEUR_03
A18: μ | B18: Heartbeat rate coefficient | C18: 0.3 | D18: 0.1 | E18: 0.5 | F18: EQ_CIRC_04
... A58: η_c | B58: Curiosity drive coefficient | C58: 0.3 | D58: 0.1 | E58: 0.5 | F58: Curiosity Drive
A61: B. 24-ENGINE REGISTRY
A62: Code | B62: Engine | C62: Fires Every | D62: Phase | E62: Status
A63: EQ_DNA_01 | B63: DNA Loop Engine | C63: 1 tick | D63: Core | E63: ✅ Verified
A64: EQ_ANAT_02 | B64: Anatomy Growth | C64: 100 ticks | D64: Core | E64: ✅ Verified
A65: EQ_NEUR_03 | B65: Neural Control | C65: 10 ticks | D65: Core | E65: ✅ Verified
A66: EQ_CIRC_04 | B66: Circulatory | C66: 1 tick | D66: Core | E66: ✅ Verified
A67: EQ_DIGE_05 | B67: Digestive & Energy | C67: 50 ticks | D67: Core | E67: ✅ Verified
A68: EQ_SENS_06 | B68: Sensory Integration | C68: 1 tick | D68: Core | E68: ✅ Verified
A69: EQ_EMOT_07 | B69: Emotion & Reinforcement | C69: 20 ticks | D69: Core | E69: ✅ Verified
A70: EQ_PRED_08 | B70: Predictive Simulation | C70: 5 ticks | D70: Core | E70: ✅ Verified
A71: EQ_ATTN_09 | B71: Attention Control | C71: 1 tick | D71: Core | E71: ✅ Verified
A72: EQ_CONS_10 | B72: Consciousness Loop | C72: 100 ticks | D72: Core | E72: ✅ Verified
A73: EQ_WRLD_11 | B73: World & NPC | C73: 50 ticks | D73: Core | E73: ✅ Verified
... A86: EQ_LEGACY_20 | B86: Legacy Projection | C86: 2000 ticks | D86: Phase 7 | E86: ⏳ Tick 96,000+

Sheet 👩 Lorraine — Parent Profile
A1: 👩 LORRAINE — PRIMARY CAREGIVER PROFILE
A2: Full biological · psychological · social · developmental profile — equivalent depth to A7DO
A3: Source: A7DO_DNA_Master_v6 · Change 🧬 DNA Loop Engine B4 to advance organism
A5: A. IDENTITY & DEMOGRAPHICS
A6: Parameter | B6: Value | C6: Unit | D6: Notes
A7: Full Name: | B7: Lorraine | D7: Primary caregiver of A7DO
A8: Role: | B8: Mother / Primary Caregiver | D8: Biological mother · sole primary attachment figure
A9: Age at A7DO Birth: | B9: 28 years | C9: years | D9: Tick 3,200 / Week 40
A10: Current Age: | B10: =ROUND(28+'🧬 DNA Loop Engine'!B5/52,1) -> 28 | C10: years | D10: Live — updates with tick
A11: Biological Sex: | B11: Female | D11: XX chromosomes
A12: Ethnicity: | B12: Mixed heritage | D12: BeenFore City population
A13: Location: | B13: H8, BeenFore Lane, BeenFore City | D13: World coordinates (1090, 880, 0)
A14: Occupation: | B14: Primary caregiver (full-time) | D14: Dedicated to A7DO development
A15: Education Level: | B15: University graduate | D15: Cognitive science background
A16: Personality Type: | B16: Nurturing · patient · emotionally intelligent | D16: MBTI: INFJ
A19: B. PHYSICAL PROFILE
A20: Parameter | B20: Value | C20: Unit | D20: Notes
A21: Height: | B21: 168 | C21: cm | D21: Adult stable
A22: Mass: | B22: 62 | C22: kg | D22: Post-pregnancy stable
A23: Heart Rate (resting): | B23: 68 | C23: bpm | D23: Healthy adult female
A24: Blood Type: | B24: A+ | D24: Rh positive
A25: Dominant Hand: | B25: Right
A26: Vision: | B26: 20/20 corrected | D26: Wears glasses
A27: Hearing: | B27: Normal range
A28: Fitness Level: | B28: Moderate | D28: Regular walking · yoga
A29: Sleep Pattern: | B29: 6–7 hours/night | C29: hours | D29: Disrupted by A7DO care
A30: Nutrition: | B30: Balanced diet | D30: Breastfeeding period: Wk 40–80
A33: C. PSYCHOLOGICAL PROFILE
A34: Trait | B34: Score (0–1) | C34: Description | D34: Impact on A7DO
A35: Attachment Style | B35: 0.92 | C35: Secure attachment — consistent, responsive | D35: A7DO bond strength = 0.95
A36: Emotional Intelligence | B36: 0.88 | C36: High EQ — reads A7DO cues accurately | D36: Emotional regulation modelling
A37: Patience | B37: 0.91 | C37: Very high — tolerates developmental delays | D37: Reduces A7DO stress hormones
A38: Verbal Stimulation | B38: 0.85 | C38: Rich language environment — 30,000 words/day | D38: Accelerates vocabulary acquisition
A39: Physical Affection | B39: 0.9 | C39: High touch · holding · skin contact | D39: Oxytocin bonding · attachment drive
A40: Cognitive Stimulation | B40: 0.82 | C40: Books · play · exploration encouragement | D40: Curiosity drive + object permanence
A41: Consistency | B41: 0.88 | C41: Predictable routines · reliable responses | D41: Prediction error reduction
A42: Stress Level | B42: 0.35 | C42: Low-moderate — occasional caregiver fatigue | D42: Cortisol transfer via interaction
A43: Mental Health | B43: 0.85 | C43: Good — no clinical conditions | D43: Stable emotional environment
A44: Resilience | B44: 0.87 | C44: High — adapts to A7DO developmental changes | D44: Models coping strategies
A47: D. LORRAINE'S ROLE BY A7DO DEVELOPMENTAL PHASE
...

Sheet 👨 China — Parent Profile
A1: 👨 CHINA — FATHER PROFILE
A2: Full biological · psychological · social · developmental profile — genetic source and secondary attachment
A3: Source: A7DO_DNA_Master_v6 · Change 🧬 DNA Loop Engine B4 to advance organism
A5: A. IDENTITY & DEMOGRAPHICS
A6: Parameter | B6: Value | C6: Unit | D6: Notes
A7: Full Name: | B7: China | D7: Father of A7DO · genetic source
A8: Role: | B8: Father / Secondary Attachment | D8: Genetic contributor · protective bond
A9: Age at A7DO Birth: | B9: 31 years | C9: years | D9: Tick 3,200 / Week 40
A10: Current Age: | B10: =ROUND(31+'🧬 DNA Loop Engine'!B5/52,1) -> 31 | C10: years | D10: Live — updates with tick
A11: Biological Sex: | B11: Male | D11: XY chromosomes
A12: Ethnicity: | B12: Mixed heritage | D12: BeenFore City population
A13: Location: | B13: H8, BeenFore Lane, BeenFore City | D13: World coordinates (1090, 880, 0)
A14: Occupation: | B14: Engineer / Technical professional | D14: Analytical · problem-solving focus
A15: Education Level: | B15: Postgraduate | D15: Engineering background
A16: Personality Type: | B16: Analytical · protective · quietly nurturing | D16: MBTI: INTJ
A19: B. PHYSICAL PROFILE
A20: Parameter | B20: Value | C20: Unit | D20: Notes
A21: Height: | B21: 182 | C21: cm | D21: Adult stable
A22: Mass: | B22: 78 | C22: kg | D22: Athletic build
A23: Heart Rate (resting): | B23: 62 | C23: bpm | D23: Fit adult male
A24: Blood Type: | B24: O+ | D24: Rh positive
A25: Dominant Hand: | B25: Right
A26: Vision: | B26: 20/20 | D26: No correction needed
A27: Hearing: | B27: Normal range
A28: Fitness Level: | B28: High | D28: Regular exercise · cycling
A29: Sleep Pattern: | B29: 7–8 hours/night | C29: hours | D29: Regular schedule
A30: Nutrition: | B30: High protein diet | D30: Athletic maintenance
A33: C. PSYCHOLOGICAL PROFILE
A34: Trait | B34: Score (0–1) | C34: Description | D34: Impact on A7DO
A35: Attachment Style | B35: 0.78 | C35: Secure-autonomous — present but less demonstrative | D35: A7DO bond strength = 0.70 (secondary)
A36: Emotional Intelligence | B36: 0.72 | C36: Good EQ — analytical approach to emotions | D36: Logical emotional modelling
A37: Patience | B37: 0.8 | C37: High — methodical problem-solver | D37: Models systematic thinking
A38: Verbal Stimulation | B38: 0.7 | C38: Moderate — technical vocabulary focus | D38: Numerical/spatial language input
A39: Physical Affection | B39: 0.75 | C39: Moderate — play-focused interaction | D39: Motor development · rough-and-tumble play
A40: Cognitive Stimulation | B40: 0.88 | C40: Very high — puzzles · building · exploration | D40: Pattern recognition · spatial cognition
A41: Consistency | B41: 0.82 | C41: High — reliable presence and routines | D41: Secondary attachment security
A42: Stress Level | B42: 0.3 | C42: Low — work-life balance maintained | D42: Calm modelling · stress buffer
A43: Mental Health | B43: 0.88 | C43: Excellent — no clinical conditions | D43: Stable secondary environment
A44: Resilience | B44: 0.9 | C44: Very high — engineering mindset | D44: Models problem-solving under pressure
A47: D. CHINA'S ROLE BY A7DO DEVELOPMENTAL PHASE
...
